![https://s3-us-west-2.amazonaws.com/secure.notion-static.com/a3c05fb0-9c54-4da3-b2da-80c1a92636da/Untitled.png](https://s3-us-west-2.amazonaws.com/secure.notion-static.com/a3c05fb0-9c54-4da3-b2da-80c1a92636da/Untitled.png)

오늘은 돌려놓은 모델 에러를 해결하려고 한다.

```python
Traceback (most recent call last):
  File "train.py", line 323, in <module>
    train()
  File "train.py", line 84, in train
    points_batch, mask_batch = get_points(x_batch)
  File "train.py", line 179, in get_points
    model = load_model(args["model"])
  File "C:\Users\dw\anaconda3\envs\myVEnv\lib\site-packages\tensorflow\python\keras\saving\save.py", line 207, in load_model
    compile)
  File "C:\Users\dw\anaconda3\envs\myVEnv\lib\site-packages\tensorflow\python\keras\saving\hdf5_format.py", line 187, in load_model_from_hdf5
    load_weights_from_hdf5_group(f['model_weights'], model.layers)
  File "C:\Users\dw\anaconda3\envs\myVEnv\lib\site-packages\tensorflow\python\keras\saving\hdf5_format.py", line 710, in load_weights_from_hdf5_group
    K.batch_set_value(weight_value_tuples)
  File "C:\Users\dw\anaconda3\envs\myVEnv\lib\site-packages\tensorflow\python\util\dispatch.py", line 201, in wrapper
    return target(*args, **kwargs)
  File "C:\Users\dw\anaconda3\envs\myVEnv\lib\site-packages\tensorflow\python\keras\backend.py", line 3731, in batch_set_value
    get_session().run(assign_ops, feed_dict=feed_dict)
  File "C:\Users\dw\anaconda3\envs\myVEnv\lib\site-packages\tensorflow\python\keras\backend.py", line 644, in get_session
    _initialize_variables(session)
  File "C:\Users\dw\anaconda3\envs\myVEnv\lib\site-packages\tensorflow\python\keras\backend.py", line 1101, in _initialize_variables
    session.run(variables_module.variables_initializer(uninitialized_vars))
  File "C:\Users\dw\anaconda3\envs\myVEnv\lib\site-packages\tensorflow\python\client\session.py", line 968, in run
    run_metadata_ptr)
  File "C:\Users\dw\anaconda3\envs\myVEnv\lib\site-packages\tensorflow\python\client\session.py", line 1191, in _run
    feed_dict_tensor, options, run_metadata)
  File "C:\Users\dw\anaconda3\envs\myVEnv\lib\site-packages\tensorflow\python\client\session.py", line 1369, in _do_run
    run_metadata)
  File "C:\Users\dw\anaconda3\envs\myVEnv\lib\site-packages\tensorflow\python\client\session.py", line 1375, in _do_call
    return fn(*args)
  File "C:\Users\dw\anaconda3\envs\myVEnv\lib\site-packages\tensorflow\python\client\session.py", line 1358, in _run_fn
    self._extend_graph()
  File "C:\Users\dw\anaconda3\envs\myVEnv\lib\site-packages\tensorflow\python\client\session.py", line 1398, in _extend_graph
    tf_session.ExtendSession(self._session)
MemoryError: bad allocation

(myVEnv) C:\Users\dw\github_repository\senier_project\GAN\glcic_test\src-upgraded>
(myVEnv) C:\Users\dw\github_repository\senier_project\GAN\glcic_test\src-upgraded>
```

자꾸 50%에서 멈추고 위와 같은 에러문이 뜬다.

+ 매일매일 새로운 에러가 나온다. 어제 모델 돌려놓고 잤는데, 아침에 유튜브 노래 트니까 갑자기 컴퓨터 블루스크린 나오고(블루스크린에서도 page fault 에러가 떴다), 모델 돌려놓은 것은 사진 batch 파일(16개세트) 하나를 학습시키는데, 50%에서 계속 MemoryError: bad allocation 이 뜬다. 아마 블루스크린(page fault 나온 것도 졸작 모델 돌린거 영향이 있을 듯;;

+ 구글링 해보니까 RAM이 부족해서 생기는 문제라고 한다.
+ google colab으로 한번 돌려보고 안되면 다른 방법을 찾을 예정.
