```python
During handling of the above exception, another exception occurred:

Traceback (most recent call last):
  File "train.py", line 228, in <module>
    train()
  File "train.py", line 98, in train
    saver.save(sess, './backup/latest', write_meta_graph=False)
  File "/usr/local/lib/python3.7/dist-packages/tensorflow/python/training/saver.py", line 1201, in save
    raise exc
  File "/usr/local/lib/python3.7/dist-packages/tensorflow/python/training/saver.py", line 1184, in save
    {self.saver_def.filename_tensor_name: checkpoint_file})
  File "/usr/local/lib/python3.7/dist-packages/tensorflow/python/client/session.py", line 968, in run
    run_metadata_ptr)
  File "/usr/local/lib/python3.7/dist-packages/tensorflow/python/client/session.py", line 1191, in _run
    feed_dict_tensor, options, run_metadata)
  File "/usr/local/lib/python3.7/dist-packages/tensorflow/python/client/session.py", line 1369, in _do_run
    run_metadata)
  File "/usr/local/lib/python3.7/dist-packages/tensorflow/python/client/session.py", line 1394, in _do_call
    raise type(e)(node_def, op, message)
tensorflow.python.framework.errors_impl.FailedPreconditionError: 2 root error(s) found.
  (0) Failed precondition: Error while reading resource variable block_1_expand_BN_111/moving_mean from Container: localhost. This could mean that the variable was uninitialized. Not found: Resource localhost/block_1_expand_BN_111/moving_mean/N10tensorflow3VarE does not exist.
	 [[node block_1_expand_BN_111/moving_mean/Read/ReadVariableOp (defined at train.py:173) ]]
	 [[decay_3/Read/ReadVariableOp/_98861]]
  (1) Failed precondition: Error while reading resource variable block_1_expand_BN_111/moving_mean from Container: localhost. This could mean that the variable was uninitialized. Not found: Resource localhost/block_1_expand_BN_111/moving_mean/N10tensorflow3VarE does not exist.
	 [[node block_1_expand_BN_111/moving_mean/Read/ReadVariableOp (defined at train.py:173) ]]
0 successful operations.
0 derived errors ignored.

Original stack trace for 'block_1_expand_BN_111/moving_mean/Read/ReadVariableOp':
  File "train.py", line 228, in <module>
    train()
  File "train.py", line 82, in train
    points_batch, mask_batch = get_points(x_batch)
  File "train.py", line 173, in get_points
    model = load_model(args["model"])
  File "/usr/local/lib/python3.7/dist-packages/tensorflow/python/keras/saving/save.py", line 207, in load_model
    compile)
  File "/usr/local/lib/python3.7/dist-packages/tensorflow/python/keras/saving/hdf5_format.py", line 184, in load_model_from_hdf5
    custom_objects=custom_objects)
  File "/usr/local/lib/python3.7/dist-packages/tensorflow/python/keras/saving/model_config.py", line 64, in model_from_config
    return deserialize(config, custom_objects=custom_objects)
  File "/usr/local/lib/python3.7/dist-packages/tensorflow/python/keras/layers/serialization.py", line 177, in deserialize
    printable_module_name='layer')
  File "/usr/local/lib/python3.7/dist-packages/tensorflow/python/keras/utils/generic_utils.py", line 358, in deserialize_keras_object
    list(custom_objects.items())))
  File "/usr/local/lib/python3.7/dist-packages/tensorflow/python/keras/engine/training.py", line 2262, in from_config
    config, custom_objects=custom_objects)
  File "/usr/local/lib/python3.7/dist-packages/tensorflow/python/keras/engine/functional.py", line 669, in from_config
    config, custom_objects)
  File "/usr/local/lib/python3.7/dist-packages/tensorflow/python/keras/engine/functional.py", line 1285, in reconstruct_from_config
    process_node(layer, node_data)
  File "/usr/local/lib/python3.7/dist-packages/tensorflow/python/keras/engine/functional.py", line 1233, in process_node
    output_tensors = layer(input_tensors, **kwargs)
  File "/usr/local/lib/python3.7/dist-packages/tensorflow/python/keras/engine/base_layer_v1.py", line 766, in __call__
    self._maybe_build(inputs)
  File "/usr/local/lib/python3.7/dist-packages/tensorflow/python/keras/engine/base_layer_v1.py", line 2106, in _maybe_build
    self.build(input_shapes)
  File "/usr/local/lib/python3.7/dist-packages/tensorflow/python/keras/layers/normalization.py", line 439, in build
    experimental_autocast=False)
  File "/usr/local/lib/python3.7/dist-packages/tensorflow/python/keras/engine/base_layer_v1.py", line 457, in add_weight
    caching_device=caching_device)
  File "/usr/local/lib/python3.7/dist-packages/tensorflow/python/training/tracking/base.py", line 810, in _add_variable_with_custom_getter
    **kwargs_for_getter)
  File "/usr/local/lib/python3.7/dist-packages/tensorflow/python/keras/engine/base_layer_utils.py", line 142, in make_variable
    shape=variable_shape if variable_shape else None)
  File "/usr/local/lib/python3.7/dist-packages/tensorflow/python/ops/variables.py", line 260, in __call__
    return cls._variable_v1_call(*args, **kwargs)
  File "/usr/local/lib/python3.7/dist-packages/tensorflow/python/ops/variables.py", line 221, in _variable_v1_call
    shape=shape)
  File "/usr/local/lib/python3.7/dist-packages/tensorflow/python/ops/variables.py", line 199, in <lambda>
    previous_getter = lambda **kwargs: default_variable_creator(None, **kwargs)
  File "/usr/local/lib/python3.7/dist-packages/tensorflow/python/ops/variable_scope.py", line 2618, in default_variable_creator
    shape=shape)
  File "/usr/local/lib/python3.7/dist-packages/tensorflow/python/ops/variables.py", line 264, in __call__
    return super(VariableMetaclass, cls).__call__(*args, **kwargs)
  File "/usr/local/lib/python3.7/dist-packages/tensorflow/python/ops/resource_variable_ops.py", line 1585, in __init__
    distribute_strategy=distribute_strategy)
  File "/usr/local/lib/python3.7/dist-packages/tensorflow/python/ops/resource_variable_ops.py", line 1767, in _init_from_args
    value = gen_resource_variable_ops.read_variable_op(handle, dtype)
  File "/usr/local/lib/python3.7/dist-packages/tensorflow/python/ops/gen_resource_variable_ops.py", line 485, in read_variable_op
    "ReadVariableOp", resource=resource, dtype=dtype, name=name)
  File "/usr/local/lib/python3.7/dist-packages/tensorflow/python/framework/op_def_library.py", line 750, in _apply_op_helper
    attrs=attr_protos, op_def=op_def)
  File "/usr/local/lib/python3.7/dist-packages/tensorflow/python/framework/ops.py", line 3536, in _create_op_internal
    op_def=op_def)
  File "/usr/local/lib/python3.7/dist-packages/tensorflow/python/framework/ops.py", line 1990, in __init__
    self._traceback = tf_stack.extract_stack()
```

에러가 똑같이 난다. 

이는 "문제는 작업 (계층) 초기화와 관련이 있습니다. tf.initialize_all_variables () 또는 체크 포인트 로딩 부분 이 있는지 확인하십시오." 와 같은 답변을 얻었다.  아래와 같이 수정하자.

```python
tf.initialize_all_variables()
saver = tf.train.Saver()
saver.restore(sess, checkpoint_path)
```

시간도 1개의 batch를 끝낼 때 1시간~2시간 걸려서 코드가 돌아간다고 해도 시간이 너무 오래걸려 새로운 모델을 같이 찾아본다.

저번 멘토님 추천

```python
안녕하세요. 졸업과제 멘토의견서 보내드립니다.

지난번에 공유해주신 프로세스 관련해서 Object Detection을 넣는 부분에 대해서 제 개인적인 의견은 
잘 안될 가능성이 높아보입니다.

심사의견에도 썼는데 이렇게되면 GAN의 성능과 Object Detection 
두 모델에 대한 성능에 의존해야합니다.

지금 진행하시는 기술의 분야는 Image Inpainting이라는 분야입니다.

제 생각은 GAN모델을 개선해야할 것 같은데요 아래 링크를 참고해보세요.

U-Net구조에 Gated Convolution을 사용할 수도 있고, Encoder-Decoder 구조를 
사용해볼 수도 있습니다.

https://wdprogrammer.tistory.com/71

https://towardsdatascience.com/a-practical-generative-deep-image-inpainting-approach-1c99fef68bd7

감사합니다
```

[https://github.com/JiahuiYu/generative_inpainting](https://github.com/JiahuiYu/generative_inpainting)

위 깃허브 소스코드를 테스트해본다.
