기존 local에서 돌렸을 때 RAM 문제가 (memory error : bad allocation) 있었는데, colab에서는 이는 해결되고 다른 에러가 뜬다.
colab으로 돌렸을 때 한 번의 배치(16)로 학습시킨 후에 다음과 같이 에러가 뜬다.

```
100% 12/12 [3:44:32<00:00, 1122.70s/it]
yes?
yes
Traceback (most recent call last):
  File "/usr/local/lib/python3.7/dist-packages/tensorflow/python/client/session.py", line 1375, in _do_call
    return fn(*args)
  File "/usr/local/lib/python3.7/dist-packages/tensorflow/python/client/session.py", line 1360, in _run_fn
    target_list, run_metadata)
  File "/usr/local/lib/python3.7/dist-packages/tensorflow/python/client/session.py", line 1453, in _call_tf_sessionrun
    run_metadata)
tensorflow.python.framework.errors_impl.FailedPreconditionError: 2 root error(s) found.
  (0) Failed precondition: Error while reading resource variable Conv_1_bn_24/moving_mean from Container: localhost. This could mean that the variable was uninitialized. Not found: Resource localhost/Conv_1_bn_24/moving_mean/N10tensorflow3VarE does not exist.
	 [[{{node Conv_1_bn_24/moving_mean/Read/ReadVariableOp}}]]
	 [[block_3_project_BN_10/moving_mean/Read/ReadVariableOp/_61019]]
  (1) Failed precondition: Error while reading resource variable Conv_1_bn_24/moving_mean from Container: localhost. This could mean that the variable was uninitialized. Not found: Resource localhost/Conv_1_bn_24/moving_mean/N10tensorflow3VarE does not exist.
	 [[{{node Conv_1_bn_24/moving_mean/Read/ReadVariableOp}}]]
0 successful operations.
0 derived errors ignored.

During handling of the above exception, another exception occurred:

Traceback (most recent call last):
  File "train.py", line 323, in <module>
    train()
  File "train.py", line 100, in train
    saver.save(sess, './backup/latest', write_meta_graph=False)
  File "/usr/local/lib/python3.7/dist-packages/tensorflow/python/training/saver.py", line 1201, in save
    raise exc
  File "/usr/local/lib/python3.7/dist-packages/tensorflow/python/training/saver.py", line 1184, in save
    {self.saver_def.filename_tensor_name: checkpoint_file})
  File "/usr/local/lib/python3.7/dist-packages/tensorflow/python/client/session.py", line 968, in run
    run_metadata_ptr)
  File "/usr/local/lib/python3.7/dist-packages/tensorflow/python/client/session.py", line 1191, in _run
    feed_dict_tensor, options, run_metadata)
  File "/usr/local/lib/python3.7/dist-packages/tensorflow/python/client/session.py", line 1369, in _do_run
    run_metadata)
  File "/usr/local/lib/python3.7/dist-packages/tensorflow/python/client/session.py", line 1394, in _do_call
    raise type(e)(node_def, op, message)
tensorflow.python.framework.errors_impl.FailedPreconditionError: 2 root error(s) found.
  (0) Failed precondition: Error while reading resource variable Conv_1_bn_24/moving_mean from Container: localhost. This could mean that the variable was uninitialized. Not found: Resource localhost/Conv_1_bn_24/moving_mean/N10tensorflow3VarE does not exist.
	 [[node Conv_1_bn_24/moving_mean/Read/ReadVariableOp (defined at train.py:179) ]]
	 [[block_3_project_BN_10/moving_mean/Read/ReadVariableOp/_61019]]
  (1) Failed precondition: Error while reading resource variable Conv_1_bn_24/moving_mean from Container: localhost. This could mean that the variable was uninitialized. Not found: Resource localhost/Conv_1_bn_24/moving_mean/N10tensorflow3VarE does not exist.
	 [[node Conv_1_bn_24/moving_mean/Read/ReadVariableOp (defined at train.py:179) ]]
0 successful operations.
0 derived errors ignored.

Original stack trace for 'Conv_1_bn_24/moving_mean/Read/ReadVariableOp':
  File "train.py", line 323, in <module>
    train()
  File "train.py", line 84, in train
    points_batch, mask_batch = get_points(x_batch)
  File "train.py", line 179, in get_points
    model = load_model(args["model"])
  File "/usr/local/lib/python3.7/dist-packages/tensorflow/python/keras/saving/save.py", line 207, in load_model
    compile)
  File "/usr/local/lib/python3.7/dist-packages/tensorflow/python/keras/saving/hdf5_format.py", line 184, in load_model_from_hdf5
    custom_objects=custom_objects)
  File "/usr/local/lib/python3.7/dist-packages/tensorflow/python/keras/saving/model_config.py", line 64, in model_from_config
    return deserialize(config, custom_objects=custom_objects)
  File "/usr/local/lib/python3.7/dist-packages/tensorflow/python/keras/layers/serialization.py", line 177, in deserialize
    printable_module_name='layer')
  File "/usr/local/lib/python3.7/dist-packages/tensorflow/python/keras/utils/generic_utils.py", line 358, in deserialize_keras_object
    list(custom_objects.items())))
  File "/usr/local/lib/python3.7/dist-packages/tensorflow/python/keras/engine/training.py", line 2262, in from_config
    config, custom_objects=custom_objects)
  File "/usr/local/lib/python3.7/dist-packages/tensorflow/python/keras/engine/functional.py", line 669, in from_config
    config, custom_objects)
  File "/usr/local/lib/python3.7/dist-packages/tensorflow/python/keras/engine/functional.py", line 1285, in reconstruct_from_config
    process_node(layer, node_data)
  File "/usr/local/lib/python3.7/dist-packages/tensorflow/python/keras/engine/functional.py", line 1233, in process_node
    output_tensors = layer(input_tensors, **kwargs)
  File "/usr/local/lib/python3.7/dist-packages/tensorflow/python/keras/engine/base_layer_v1.py", line 766, in __call__
    self._maybe_build(inputs)
  File "/usr/local/lib/python3.7/dist-packages/tensorflow/python/keras/engine/base_layer_v1.py", line 2106, in _maybe_build
    self.build(input_shapes)
  File "/usr/local/lib/python3.7/dist-packages/tensorflow/python/keras/layers/normalization.py", line 439, in build
    experimental_autocast=False)
  File "/usr/local/lib/python3.7/dist-packages/tensorflow/python/keras/engine/base_layer_v1.py", line 457, in add_weight
    caching_device=caching_device)
  File "/usr/local/lib/python3.7/dist-packages/tensorflow/python/training/tracking/base.py", line 810, in _add_variable_with_custom_getter
    **kwargs_for_getter)
  File "/usr/local/lib/python3.7/dist-packages/tensorflow/python/keras/engine/base_layer_utils.py", line 142, in make_variable
    shape=variable_shape if variable_shape else None)
  File "/usr/local/lib/python3.7/dist-packages/tensorflow/python/ops/variables.py", line 260, in __call__
    return cls._variable_v1_call(*args, **kwargs)
  File "/usr/local/lib/python3.7/dist-packages/tensorflow/python/ops/variables.py", line 221, in _variable_v1_call
    shape=shape)
  File "/usr/local/lib/python3.7/dist-packages/tensorflow/python/ops/variables.py", line 199, in <lambda>
    previous_getter = lambda **kwargs: default_variable_creator(None, **kwargs)
  File "/usr/local/lib/python3.7/dist-packages/tensorflow/python/ops/variable_scope.py", line 2618, in default_variable_creator
    shape=shape)
  File "/usr/local/lib/python3.7/dist-packages/tensorflow/python/ops/variables.py", line 264, in __call__
    return super(VariableMetaclass, cls).__call__(*args, **kwargs)
  File "/usr/local/lib/python3.7/dist-packages/tensorflow/python/ops/resource_variable_ops.py", line 1585, in __init__
    distribute_strategy=distribute_strategy)
  File "/usr/local/lib/python3.7/dist-packages/tensorflow/python/ops/resource_variable_ops.py", line 1767, in _init_from_args
    value = gen_resource_variable_ops.read_variable_op(handle, dtype)
  File "/usr/local/lib/python3.7/dist-packages/tensorflow/python/ops/gen_resource_variable_ops.py", line 485, in read_variable_op
    "ReadVariableOp", resource=resource, dtype=dtype, name=name)
  File "/usr/local/lib/python3.7/dist-packages/tensorflow/python/framework/op_def_library.py", line 750, in _apply_op_helper
    attrs=attr_protos, op_def=op_def)
  File "/usr/local/lib/python3.7/dist-packages/tensorflow/python/framework/ops.py", line 3536, in _create_op_internal
    op_def=op_def)
  File "/usr/local/lib/python3.7/dist-packages/tensorflow/python/framework/ops.py", line 1990, in __init__
    self._traceback = tf_stack.extract_stack()
    ```
  
