기존 local에서 돌렸을 때 RAM 문제가 (memory error : bad allocation) 있었는데, colab에서는 이는 해결되고 다른 에러가 뜬다.
colab으로 돌렸을 때 한 번의 배치(16)로 학습시킨 후에 다음과 같이 에러가 뜬다.

## 1.에러1

```cpp

100% 12/12 [3:44:32<00:00, 1122.70s/it]
yes?
yes
Traceback (most recent call last):
  File "/usr/local/lib/python3.7/dist-packages/tensorflow/python/client/session.py", line 1375, in _do_call
    return fn(*args)
  File "/usr/local/lib/python3.7/dist-packages/tensorflow/python/client/session.py", line 1360, in _run_fn
    target_list, run_metadata)
  File "/usr/local/lib/python3.7/dist-packages/tensorflow/python/client/session.py", line 1453, in _call_tf_sessionrun
    run_metadata)
tensorflow.python.framework.errors_impl.FailedPreconditionError: 2 root error(s) found.
  (0) Failed precondition: Error while reading resource variable Conv_1_bn_24/moving_mean from Container: localhost. This could mean that the variable was uninitialized. Not found: Resource localhost/Conv_1_bn_24/moving_mean/N10tensorflow3VarE does not exist.
	 [[{{node Conv_1_bn_24/moving_mean/Read/ReadVariableOp}}]]
	 [[block_3_project_BN_10/moving_mean/Read/ReadVariableOp/_61019]]
  (1) Failed precondition: Error while reading resource variable Conv_1_bn_24/moving_mean from Container: localhost. This could mean that the variable was uninitialized. Not found: Resource localhost/Conv_1_bn_24/moving_mean/N10tensorflow3VarE does not exist.
	 [[{{node Conv_1_bn_24/moving_mean/Read/ReadVariableOp}}]]
0 successful operations.
0 derived errors ignored.

During handling of the above exception, another exception occurred:

Traceback (most recent call last):
  File "train.py", line 323, in <module>
    train()
  File "train.py", line 100, in train
    saver.save(sess, './backup/latest', write_meta_graph=False)
  File "/usr/local/lib/python3.7/dist-packages/tensorflow/python/training/saver.py", line 1201, in save
    raise exc
  File "/usr/local/lib/python3.7/dist-packages/tensorflow/python/training/saver.py", line 1184, in save
    {self.saver_def.filename_tensor_name: checkpoint_file})
  File "/usr/local/lib/python3.7/dist-packages/tensorflow/python/client/session.py", line 968, in run
    run_metadata_ptr)
  File "/usr/local/lib/python3.7/dist-packages/tensorflow/python/client/session.py", line 1191, in _run
    feed_dict_tensor, options, run_metadata)
  File "/usr/local/lib/python3.7/dist-packages/tensorflow/python/client/session.py", line 1369, in _do_run
    run_metadata)
  File "/usr/local/lib/python3.7/dist-packages/tensorflow/python/client/session.py", line 1394, in _do_call
    raise type(e)(node_def, op, message)
tensorflow.python.framework.errors_impl.FailedPreconditionError: 2 root error(s) found.
  (0) Failed precondition: Error while reading resource variable Conv_1_bn_24/moving_mean from Container: localhost. This could mean that the variable was uninitialized. Not found: Resource localhost/Conv_1_bn_24/moving_mean/N10tensorflow3VarE does not exist.
	 [[node Conv_1_bn_24/moving_mean/Read/ReadVariableOp (defined at train.py:179) ]]
	 [[block_3_project_BN_10/moving_mean/Read/ReadVariableOp/_61019]]
  (1) Failed precondition: Error while reading resource variable Conv_1_bn_24/moving_mean from Container: localhost. This could mean that the variable was uninitialized. Not found: Resource localhost/Conv_1_bn_24/moving_mean/N10tensorflow3VarE does not exist.
	 [[node Conv_1_bn_24/moving_mean/Read/ReadVariableOp (defined at train.py:179) ]]
0 successful operations.
0 derived errors ignored.

Original stack trace for 'Conv_1_bn_24/moving_mean/Read/ReadVariableOp':
  File "train.py", line 323, in <module>
    train()
  File "train.py", line 84, in train
    points_batch, mask_batch = get_points(x_batch)
  File "train.py", line 179, in get_points
    model = load_model(args["model"])
  File "/usr/local/lib/python3.7/dist-packages/tensorflow/python/keras/saving/save.py", line 207, in load_model
    compile)
  File "/usr/local/lib/python3.7/dist-packages/tensorflow/python/keras/saving/hdf5_format.py", line 184, in load_model_from_hdf5
    custom_objects=custom_objects)
  File "/usr/local/lib/python3.7/dist-packages/tensorflow/python/keras/saving/model_config.py", line 64, in model_from_config
    return deserialize(config, custom_objects=custom_objects)
  File "/usr/local/lib/python3.7/dist-packages/tensorflow/python/keras/layers/serialization.py", line 177, in deserialize
    printable_module_name='layer')
  File "/usr/local/lib/python3.7/dist-packages/tensorflow/python/keras/utils/generic_utils.py", line 358, in deserialize_keras_object
    list(custom_objects.items())))
  File "/usr/local/lib/python3.7/dist-packages/tensorflow/python/keras/engine/training.py", line 2262, in from_config
    config, custom_objects=custom_objects)
  File "/usr/local/lib/python3.7/dist-packages/tensorflow/python/keras/engine/functional.py", line 669, in from_config
    config, custom_objects)
  File "/usr/local/lib/python3.7/dist-packages/tensorflow/python/keras/engine/functional.py", line 1285, in reconstruct_from_config
    process_node(layer, node_data)
  File "/usr/local/lib/python3.7/dist-packages/tensorflow/python/keras/engine/functional.py", line 1233, in process_node
    output_tensors = layer(input_tensors, **kwargs)
  File "/usr/local/lib/python3.7/dist-packages/tensorflow/python/keras/engine/base_layer_v1.py", line 766, in __call__
    self._maybe_build(inputs)
  File "/usr/local/lib/python3.7/dist-packages/tensorflow/python/keras/engine/base_layer_v1.py", line 2106, in _maybe_build
    self.build(input_shapes)
  File "/usr/local/lib/python3.7/dist-packages/tensorflow/python/keras/layers/normalization.py", line 439, in build
    experimental_autocast=False)
  File "/usr/local/lib/python3.7/dist-packages/tensorflow/python/keras/engine/base_layer_v1.py", line 457, in add_weight
    caching_device=caching_device)
  File "/usr/local/lib/python3.7/dist-packages/tensorflow/python/training/tracking/base.py", line 810, in _add_variable_with_custom_getter
    **kwargs_for_getter)
  File "/usr/local/lib/python3.7/dist-packages/tensorflow/python/keras/engine/base_layer_utils.py", line 142, in make_variable
    shape=variable_shape if variable_shape else None)
  File "/usr/local/lib/python3.7/dist-packages/tensorflow/python/ops/variables.py", line 260, in __call__
    return cls._variable_v1_call(*args, **kwargs)
  File "/usr/local/lib/python3.7/dist-packages/tensorflow/python/ops/variables.py", line 221, in _variable_v1_call
    shape=shape)
  File "/usr/local/lib/python3.7/dist-packages/tensorflow/python/ops/variables.py", line 199, in <lambda>
    previous_getter = lambda **kwargs: default_variable_creator(None, **kwargs)
  File "/usr/local/lib/python3.7/dist-packages/tensorflow/python/ops/variable_scope.py", line 2618, in default_variable_creator
    shape=shape)
  File "/usr/local/lib/python3.7/dist-packages/tensorflow/python/ops/variables.py", line 264, in __call__
    return super(VariableMetaclass, cls).__call__(*args, **kwargs)
  File "/usr/local/lib/python3.7/dist-packages/tensorflow/python/ops/resource_variable_ops.py", line 1585, in __init__
    distribute_strategy=distribute_strategy)
  File "/usr/local/lib/python3.7/dist-packages/tensorflow/python/ops/resource_variable_ops.py", line 1767, in _init_from_args
    value = gen_resource_variable_ops.read_variable_op(handle, dtype)
  File "/usr/local/lib/python3.7/dist-packages/tensorflow/python/ops/gen_resource_variable_ops.py", line 485, in read_variable_op
    "ReadVariableOp", resource=resource, dtype=dtype, name=name)
  File "/usr/local/lib/python3.7/dist-packages/tensorflow/python/framework/op_def_library.py", line 750, in _apply_op_helper
    attrs=attr_protos, op_def=op_def)
  File "/usr/local/lib/python3.7/dist-packages/tensorflow/python/framework/ops.py", line 3536, in _create_op_internal
    op_def=op_def)
  File "/usr/local/lib/python3.7/dist-packages/tensorflow/python/framework/ops.py", line 1990, in __init__
    self._traceback = tf_stack.extract_stack()
   

```

### 2. **ddepth 에러 (해결)**

```cpp
File "train.py", line 82, in train
    points_batch, mask_batch = get_points(x_batch)
  File "train.py", line 191, in get_points
    blob = cv2.dnn.blobFromImage(image,1.0,(224, 224),(104.0, 177.0, 123.0))
cv2.error: OpenCV(4.1.2) /io/opencv/modules/dnn/src/dnn.cpp:301: error: (-215:Assertion failed) image.depth() == blob_.depth() in function 'blobFromImages'
```

```cpp
image = cv2.imread(args["image"])
```

위에서 가져온 이미지 파일이 아닌

train_batch[i] 파일을 사용하면 위와 같은 에러가 나온다.

```
blob = cv2.dnn.blobFromImage(image,1.0/255, (224, 224), (0, 0, 0),
                                       swapRB=False, crop=False,ddepth=None)

```

train.py의 get_points(x_batch) 함수의 blob 부분에서 ddepth error 가 난다.

```
  File "train.py", line 82, in train
    points_batch, mask_batch = get_points(x_batch)
  File "train.py", line 195, in get_points
    # pass the blob through the network and obtain the face detections
cv2.error: OpenCV(4.1.2) /io/opencv/modules/dnn/src/dnn.cpp:301: error: (-215:Assertion failed) image.depth() == blob_.depth() in function 'blobFromImages'

```

에러문은 위와 같다. blob문제인데 이전의 실행되는 이미지는 픽셀을 정규화하지 않았고, 에러가 나는 이미지는 픽셀 정규화를 하고 나온 이미지이다.

그럼 이미지 정규화한 부분을 삭제하고 실행해보자.

```python
#x_train = np.array([a / 127.5 - 1 for a in x_train])
#x_test = np.array([a / 127.5 - 1 for a in x_test])
```

정규화하는 부분을 주석처리했다. 결과는 ?

```cpp
!python [train.py](http://train.py/)
```

돌아간다 !! 이 문제는 위와 같이 정규화를 해서 마이너스 값을 일어난 것이라 생각된다. 근데 이제는 정규화한 이미지를 정규화안한 이미지로 사용할 때 train에서 무엇을 바꿔야할 지 보자.
