오늘 해야할 것

- mask_image()에서 일반 image 말고 batch 파일을 받아서 사용하게 만들기 60%
    - **blob 에러 해결하기**

```python
cv2.error: OpenCV(4.5.1) C:\Users\appveyor\AppData\Local\Temp\1\pip-req-build-vijyisc5\opencv\modules\dnn\src\dnn.cpp:381: error: (-215:Assertion failed) image.depth() == blob_.depth() in function 'cv::dnn::dnn4_v20201117::blobFromImages'
```

현재 npy로 저장한 파일 x_batch(16,128,128,3)를 하나씩 꺼내쓰면 에러가 생기고 로컬 파일을 가져오면 에러가 생기지 않는다. 둘 다 resize로 (128,128,3) 으로 reshape를 해서 받아오는 데도 blob에서 에러가 생기는데, 뭐가 문제인지 모르겠다. 현재 get_points의 형식은 맞춰놓았는데, 이 부분만 해결하면 될거같다. (아닐수도..)

( x_batch[i] 와 같이 (128,128,3) 사이즈로 고쳐서 이미지의 마스크 부분을 찾게 하는 작업)

```python
"train.py", line 198, in get_points
    blob = cv2.dnn.blobFromImage(image,1.0,(224, 224),(104.0, 177.0, 123.0))
cv2.error: OpenCV(4.5.1) C:\Users\appveyor\AppData\Local\Temp\1\pip-req-build-vijyisc5\opencv\modules\dnn\src\dnn.cpp:381: error: (-215:Assertion failed) image.depth() == blob_.depth() in function 'cv::dnn::dnn4_v20201117::blobFromImages'
```

일단 images/pic1.jpeg 파일의 mask 좌표를 return하게 해서 돌려보자. 시간이 오래걸려서 밤새 돌려야할듯.
